Workbook

Sheet Program
A1: All times UAE time | B1: Click on the +/- icon on left trail to expand/collapse details of sessions
B2: Rooms 1 | C2: Room 2 | D2: Room 3 | E2: Room 4 | F2: Room 5 | G2: Room 6 | H2: Room 7 | I2: Room 8 | J2: Room 9 | K2: Room 10 | L2: Room 11 | M2: Room 12 | N2: Room 13 | O2: Room 14
A3: 46202
A4: 10:00 - 13:30 | B4: tut 1 | C4: tut 2 | D4: tut 3 | E4: wk1101 | F4: wk2001 | G4: wk2301 | H4: wk0900 | I4: wk1900 | J4: wk2100 | K4: wk2200 | L4: wk0100 | N4: Web4All
B5: =IFERROR(__xludf.DUMMYFUNCTION("TEXTJOIN(CHAR(10), TRUE,FILTER(Tutorials!$E:$E,Tutorials!$A:$A=B4))"),"Temporal Information Retrieval And Question Answering in the Age of LLMs Bhawna Piryani, Avishek Anand and Adam Jatowt") -> Temporal Information Retrieval And Question Answering in the Age of LLMs Bhawna Piryani, Avishek Anand and Adam Jatowt | C5: =IFERROR(__xludf.DUMMYFUNCTION("TEXTJOIN(CHAR(10), TRUE,FILTER(Tutorials!$E:$E,Tutorials!$A:$A=C4))"),"Out-of-distribution Generalized Generative AI Xin Wang, Yuwei Zhou, Zirui Pan and Wenwu Zhu") -> Out-of-distribution Generalized Generative AI Xin Wang, Yuwei Zhou, Zirui Pan and Wenwu Zhu | D5: =IFERROR(__xludf.DUMMYFUNCTION("TEXTJOIN(CHAR(10), TRUE,FILTER(Tutorials!$E:$E,Tutorials!$A:$A=D4))"),"Towards a Responsible Web: Economic Perspectives on Fairness in Information Retrieval Chen Xu, Clara Rus, Yuanna Liu, Marleen de Jonge, Jun Xu and Maarten de Rijke") -> Towards a Responsible Web: Economic Perspectives on Fairness in Information Retrieval Chen Xu, Clara Rus, Yuanna Liu, Marleen de Jonge, Jun Xu and Maarten de Rijke | E5: =IFERROR(__xludf.DUMMYFUNCTION("TEXTJOIN(CHAR(10), TRUE,FILTER(Workshops!$F:$F,Workshops!$A:$A=E4))"),"(LARS) part 1 - LLM & Agents for Recommendation Systems Keerthi Gopalakrishnan, Qi Xu, Aysenur Inan, Zhigang Hua, Shuang Yang and Luyi Ma https://llmandagents4recsys.github.io/") -> (LARS) part 1 - LLM & Agents for Recommendation Systems Keerthi Gopalakrishnan, Qi Xu, Aysenur Inan, Zhigang Hua, Shuang Yang and Luyi Ma https://llmandagents4recsys.github.io/ | F5: =IFERROR(__xludf.DUMMYFUNCTION("TEXTJOIN(CHAR(10), TRUE,FILTER(Workshops!$F:$F,Workshops!$A:$A=F4))"),"(WebAds) part 1 - Emerging Trends in Web Advertising Ehsan Toreini and Muadh Al Kalbani https://samsunginternet.github.io/webads26/") -> (WebAds) part 1 - Emerging Trends in Web Advertising Ehsan Toreini and Muadh Al Kalbani https://samsunginternet.github.io/webads26/ | G5: =IFERROR(__xludf.DUMMYFUNCTION("TEXTJOIN(CHAR(10), TRUE,FILTER(Workshops!$F:$F,Workshops!$A:$A=G4))"),"(ZABAPAD) part 1 - Zero-knowledge Proof and Blockchain for Web 4.0: Advancing the Post-quantum and Decentralized Era Shiho Kim, Ho Suk, Roberto Di Pietro, Davor Svetinovic, KyungHi Chang, Madhusudan Singh and Rakesh Shrestha https://zabapad.github.io") -> (ZABAPAD) part 1 - Zero-knowledge Proof and Blockchain for Web 4.0: Advancing the Post-quantum and Decentralized Era Shiho Kim, Ho Suk, Roberto Di Pietro, Davor Svetinovic, KyungHi Chang, Madhusudan Singh and Rakesh Shrestha https://zabapad.github.io | H5: =IFERROR(__xludf.DUMMYFUNCTION("TEXTJOIN(CHAR(10), TRUE,FILTER(Workshops!$F:$F,Workshops!$A:$A=H4))"),"(GLOW) - Graph-enhanced LLMs for Trustworthy Web Data Management Gianluca Bonifazi, Stefano Cirillo, Eliana Pastor and Luca Virgili https://glow-workshop.github.io/www2026/") -> (GLOW) - Graph-enhanced LLMs for Trustworthy Web Data Management Gianluca Bonifazi, Stefano Cirillo, Eliana Pastor and Luca Virgili https://glow-workshop.github.io/www2026/ | I5: =IFERROR(__xludf.DUMMYFUNCTION("TEXTJOIN(CHAR(10), TRUE,FILTER(Workshops!$F:$F,Workshops!$A:$A=I4))"),"(TML) - International Workshop on Trustworthy Multimodal Learning for Social Media Analysis Jingwei Sun,G uosheng Lin, Fengmao Lv, Tao Liang, Junlin Fang and Jianli Wang https://ttthhl.github.io/www2026-workshop/") -> (TML) - International Workshop on Trustworthy Multimodal Learning for Social Media Analysis Jingwei Sun,G uosheng Lin, Fengmao Lv, Tao Liang, Junlin Fang and Jianli Wang https://ttthhl.github.io/www2026-workshop/ | J5: =IFERROR(__xludf.DUMMYFUNCTION("TEXTJOIN(CHAR(10), TRUE,FILTER(Workshops!$F:$F,Workshops!$A:$A=J4))"),"(WebAndTheCity) - 12th International Smart City Workshop – Data-Driven Smart Cities Leonidas Anthopoulos, Marijn Janssen and Vishanth Weerakkody https://webandthecity.home.blog/") -> (WebAndTheCity) - 12th International Smart City Workshop – Data-Driven Smart Cities Leonidas Anthopoulos, Marijn Janssen and Vishanth Weerakkody https://webandthecity.home.blog/ | K5: =IFERROR(__xludf.DUMMYFUNCTION("TEXTJOIN(CHAR(10), TRUE,FILTER(Workshops!$F:$F,Workshops!$A:$A=K4))"),"(WebST) - The 2nd International Workshop on Spatio-Temporal Data Mining from the Web Yuxuan Liang, Hao Xue, Ming Jin, Fei Wang, Qingxiang Liu, Qingsong Wen, Shirui Pan and Flora Salim https://webst2026.netlify.app/") -> (WebST) - The 2nd International Workshop on Spatio-Temporal Data Mining from the Web Yuxuan Liang, Hao Xue, Ming Jin, Fei Wang, Qingxiang Liu, Qingsong Wen, Shirui Pan and Flora Salim https://webst2026.netlify.app/ | L5: =IFERROR(__xludf.DUMMYFUNCTION("TEXTJOIN(CHAR(10), TRUE,FILTER(Workshops!$F:$F,Workshops!$A:$A=L4))"),"(AAIMVT) - 1st Workshop on Applied AI and Multimodal Visualization Technologies Cesar Sanin, Edward Szczerbicki and Md Rafiqul Islam https://rafiqulislamcse24.wixsite.com/aaimvt-26") -> (AAIMVT) - 1st Workshop on Applied AI and Multimodal Visualization Technologies Cesar Sanin, Edward Szczerbicki and Md Rafiqul Islam https://rafiqulislamcse24.wixsite.com/aaimvt-26 | N5: https://www.w4a.info/2026/
A6: 13:00 - 14:00 | B6: Break
A7: 14:00- 17:30 | B7: tut 6 | C7: tut 9 | D7: tut 10 | E7: wk1102 | F7: wk2002 | G7: wk2302 | H7: wk1500 | I7: wk1300 | J7: wk0400 | K7: wk1400 | N7: Web4All
B8: =IFERROR(__xludf.DUMMYFUNCTION("TEXTJOIN(CHAR(10), TRUE,FILTER(Tutorials!$E:$E,Tutorials!$A:$A=B7))"),"Quantum-Safe, Efficient, and AI-Enhanced Blockchains for the Web: A Cooperative Tutorial on Quantum Computing, Blockchain Applications, and Data Standards Dongping Liu, Aoyu Zhang and Luyao Zhang") -> Quantum-Safe, Efficient, and AI-Enhanced Blockchains for the Web: A Cooperative Tutorial on Quantum Computing, Blockchain Applications, and Data Standards Dongping Liu, Aoyu Zhang and Luyao Zhang | C8: =IFERROR(__xludf.DUMMYFUNCTION("TEXTJOIN(CHAR(10), TRUE,FILTER(Tutorials!$E:$E,Tutorials!$A:$A=C7))"),"Bandits, LLMs, and Agentic Web Djallel Bouneffouf and Raphael Feraud") -> Bandits, LLMs, and Agentic Web Djallel Bouneffouf and Raphael Feraud | D8: =IFERROR(__xludf.DUMMYFUNCTION("TEXTJOIN(CHAR(10), TRUE,FILTER(Tutorials!$E:$E,Tutorials!$A:$A=D7))"),"Unstructured to Structured: Building Knowledge Graphs from Documents for Web Applications Qiang Sun, Yihao Ding, Sirui Li and Wei Liu") -> Unstructured to Structured: Building Knowledge Graphs from Documents for Web Applications Qiang Sun, Yihao Ding, Sirui Li and Wei Liu | E8: =IFERROR(__xludf.DUMMYFUNCTION("TEXTJOIN(CHAR(10), TRUE,FILTER(Workshops!$F:$F,Workshops!$A:$A=E7))"),"(LARS) part 2 - LLM & Agents for Recommendation Systems Keerthi Gopalakrishnan, Qi Xu, Aysenur Inan, Zhigang Hua, Shuang Yang and Luyi Ma https://llmandagents4recsys.github.io/") -> (LARS) part 2 - LLM & Agents for Recommendation Systems Keerthi Gopalakrishnan, Qi Xu, Aysenur Inan, Zhigang Hua, Shuang Yang and Luyi Ma https://llmandagents4recsys.github.io/ | F8: =IFERROR(__xludf.DUMMYFUNCTION("TEXTJOIN(CHAR(10), TRUE,FILTER(Workshops!$F:$F,Workshops!$A:$A=F7))"),"(WebAds) part 2 - Emerging Trends in Web Advertising Ehsan Toreini and Muadh Al Kalbani https://samsunginternet.github.io/webads26/") -> (WebAds) part 2 - Emerging Trends in Web Advertising Ehsan Toreini and Muadh Al Kalbani https://samsunginternet.github.io/webads26/ | G8: =IFERROR(__xludf.DUMMYFUNCTION("TEXTJOIN(CHAR(10), TRUE,FILTER(Workshops!$F:$F,Workshops!$A:$A=G7))"),"(ZABAPAD) part 2 - Zero-knowledge Proof and Blockchain for Web 4.0: Advancing the Post-quantum and Decentralized Era Shiho Kim, Ho Suk, Roberto Di Pietro, Davor Svetinovic, KyungHi Chang, Madhusudan Singh and Rakesh Shrestha https://zabapad.github.io") -> (ZABAPAD) part 2 - Zero-knowledge Proof and Blockchain for Web 4.0: Advancing the Post-quantum and Decentralized Era Shiho Kim, Ho Suk, Roberto Di Pietro, Davor Svetinovic, KyungHi Chang, Madhusudan Singh and Rakesh Shrestha https://zabapad.github.io | H8: =IFERROR(__xludf.DUMMYFUNCTION("TEXTJOIN(CHAR(10), TRUE,FILTER(Workshops!$F:$F,Workshops!$A:$A=H7))"),"(SemTech) - 4th International Workshop on AI and Semantic Technologies for the Scientific, Technical, and Legal Web Rima Dessi', Jeenu Joy, Danilo Dessi', Francesco Osborne and Hidir Aras https://semtech4stld.github.io/") -> (SemTech) - 4th International Workshop on AI and Semantic Technologies for the Scientific, Technical, and Legal Web Rima Dessi', Jeenu Joy, Danilo Dessi', Francesco Osborne and Hidir Aras https://semtech4stld.github.io/ | I8: =IFERROR(__xludf.DUMMYFUNCTION("TEXTJOIN(CHAR(10), TRUE,FILTER(Workshops!$F:$F,Workshops!$A:$A=I7))"),"(PromptEng) - Third International Workshop on Prompt Engineering for Pre-Trained Language Models Damien Graux, Sébastien Montella and Hajira Jabeen https://prompteng-ws.github.io/2026/") -> (PromptEng) - Third International Workshop on Prompt Engineering for Pre-Trained Language Models Damien Graux, Sébastien Montella and Hajira Jabeen https://prompteng-ws.github.io/2026/ | J8: =IFERROR(__xludf.DUMMYFUNCTION("TEXTJOIN(CHAR(10), TRUE,FILTER(Workshops!$F:$F,Workshops!$A:$A=J7))"),"(BeyondFacts'26) - 6th International Workshop on Computational Methods for Online Discourse Analysis Stefan Dietze, Dimitar Dimitrov, Pavlos Fafalios and Konstantin Todorov https://beyondfacts2026.wordpress.com/") -> (BeyondFacts'26) - 6th International Workshop on Computational Methods for Online Discourse Analysis Stefan Dietze, Dimitar Dimitrov, Pavlos Fafalios and Konstantin Todorov https://beyondfacts2026.wordpress.com/ | K8: =IFERROR(__xludf.DUMMYFUNCTION("TEXTJOIN(CHAR(10), TRUE,FILTER(Workshops!$F:$F,Workshops!$A:$A=K7))"),"(R2CASS) - The 2nd International Workshop on Social Science Meets Web Data: Reproducible and Reusable Computational Approaches Fakhri Momeni, Arnim Bleier, Danilo Dessi and Muhammad Taimoor Khan https://sites.google.com/view/r2cass/home") -> (R2CASS) - The 2nd International Workshop on Social Science Meets Web Data: Reproducible and Reusable Computational Approaches Fakhri Momeni, Arnim Bleier, Danilo Dessi and Muhammad Taimoor Khan https://sites.google.com/view/r2cass/home | N8: https://www.w4a.info/2026/
A10: 46203
A11: 10:00 - 13:30 | B11: tut 4 | C11: tut 7 | D11: tut 11 | E11: wk1000 | F11: wk0501 | G11: wk0601 | H11: wk1601 | I11: wk1801 | J11: wk0300 | K11: wk0200 | L11: wk1700 | M11: PhD Symposium Part 1 | N11: Web4All
B12: =IFERROR(__xludf.DUMMYFUNCTION("TEXTJOIN(CHAR(10), TRUE,FILTER(Tutorials!$E:$E,Tutorials!$A:$A=B11))"),"Next-Gen Code Development with Collaborative AI Agents Shweta Garg, Behrooz Omidvar-Tehrani, Shengyu Fu, Gauthier Guinet and Baishakhi Ray") -> Next-Gen Code Development with Collaborative AI Agents Shweta Garg, Behrooz Omidvar-Tehrani, Shengyu Fu, Gauthier Guinet and Baishakhi Ray | C12: =IFERROR(__xludf.DUMMYFUNCTION("TEXTJOIN(CHAR(10), TRUE,FILTER(Tutorials!$E:$E,Tutorials!$A:$A=C11))"),"Conversational Search: From Fundamentals to Frontiers in the Age of Agents Chuan Meng, Fengran Mo, Mohammad Aliannejadi, Jeff Dalton and Jian-Yun Nie") -> Conversational Search: From Fundamentals to Frontiers in the Age of Agents Chuan Meng, Fengran Mo, Mohammad Aliannejadi, Jeff Dalton and Jian-Yun Nie | D12: =IFERROR(__xludf.DUMMYFUNCTION("TEXTJOIN(CHAR(10), TRUE,FILTER(Tutorials!$E:$E,Tutorials!$A:$A=D11))"),"Foundations for the Agentic Web: Infrastructure, Economics, and Society Ramesh Raskar and Pradyumna Chari") -> Foundations for the Agentic Web: Infrastructure, Economics, and Society Ramesh Raskar and Pradyumna Chari | E12: =IFERROR(__xludf.DUMMYFUNCTION("TEXTJOIN(CHAR(10), TRUE,FILTER(Workshops!$F:$F,Workshops!$A:$A=E11))"),"(HCRS) - The 2nd Workshop on Human-Centered Recommender Systems Kaike Zhang, Jiakai Tang, Du Su, Shuchang Liu, Julian McAuley, Lina Yao, Qi Cao, Yue Feng and Fei Sun https://hcrec.github.io/") -> (HCRS) - The 2nd Workshop on Human-Centered Recommender Systems Kaike Zhang, Jiakai Tang, Du Su, Shuchang Liu, Julian McAuley, Lina Yao, Qi Cao, Yue Feng and Fei Sun https://hcrec.github.io/ | F12: =IFERROR(__xludf.DUMMYFUNCTION("TEXTJOIN(CHAR(10), TRUE,FILTER(Workshops!$F:$F,Workshops!$A:$A=F11))"),"(DHOW-MiLLA) part 1 - Joint Workshop on Diffusion of Harmful Content on Online Web and Countering Misinformation in the Age of LLMs and Agents Thomas Mandl, Haiming Liu, Gautam Kishore Shahi, Amit Kumar Jaiswal, Durgesh Nandini, Luis-Daniel Ibáñez, Junich"&"i Suga, Dai Yamamoto, Rahul Mishra, Rajakrishnan P. Rajkumar, Sagar Uprety, Sujit Kuma and Bornali Phukon https://dhow-workshop.github.io/2026/") -> (DHOW-MiLLA) part 1 - Joint Workshop on Diffusion of Harmful Content on Online Web and Countering Misinformation in the Age of LLMs and Agents Thomas Mandl, Haiming Liu, Gautam Kishore Shahi, Amit Kumar Jaiswal, Durgesh Nandini, Luis-Daniel Ibáñez, Junichi Suga, Dai Yamamoto, Rahul Mishra, Rajakrishnan P. Rajkumar, Sagar Uprety, Sujit Kuma and Bornali Phukon https://dhow-workshop.github.io/2026/ | G12: =IFERROR(__xludf.DUMMYFUNCTION("TEXTJOIN(CHAR(10), TRUE,FILTER(Workshops!$F:$F,Workshops!$A:$A=G11))"),"(FAAW) part 1 - International Workshop on Foundations and Architectures for the Agentic Web Abderrahmane Maaradji, Abul Ehtesham, Aditi Singh, Boualem Benatallah, Fatma Outay, Luca Muscariello, Pradyumna Chari, Ramesh Raskar, Sabrina Senatore and Yacine S"&"am https://faaw.univ-tours.fr/") -> (FAAW) part 1 - International Workshop on Foundations and Architectures for the Agentic Web Abderrahmane Maaradji, Abul Ehtesham, Aditi Singh, Boualem Benatallah, Fatma Outay, Luca Muscariello, Pradyumna Chari, Ramesh Raskar, Sabrina Senatore and Yacine Sam https://faaw.univ-tours.fr/ | H12: =IFERROR(__xludf.DUMMYFUNCTION("TEXTJOIN(CHAR(10), TRUE,FILTER(Workshops!$F:$F,Workshops!$A:$A=H11))"),"(TempWeb) part 1 - The 16th Temporal Web Analytics Workshop Marc Spaniol, France Omar Alonso and Ricardo Baeza-Yates https://temporalweb.net/") -> (TempWeb) part 1 - The 16th Temporal Web Analytics Workshop Marc Spaniol, France Omar Alonso and Ricardo Baeza-Yates https://temporalweb.net/ | I12: =IFERROR(__xludf.DUMMYFUNCTION("TEXTJOIN(CHAR(10), TRUE,FILTER(Workshops!$F:$F,Workshops!$A:$A=I11))"),"(TIME) part 1 - 2nd International Workshop on Transformative Insights in Multi-faceted Evaluation Lei Wang, Md Zakir Hossain, Tom Gedeon, Syed Mohammed Shamsul Islam. Rafiqul Islam. Yasmeen George and Shreya Ghosh https://time.griffith.edu.au/workshop/"&"time2026/") -> (TIME) part 1 - 2nd International Workshop on Transformative Insights in Multi-faceted Evaluation Lei Wang, Md Zakir Hossain, Tom Gedeon, Syed Mohammed Shamsul Islam. Rafiqul Islam. Yasmeen George and Shreya Ghosh https://time.griffith.edu.au/workshop/time2026/ | J12: =IFERROR(__xludf.DUMMYFUNCTION("TEXTJOIN(CHAR(10), TRUE,FILTER(Workshops!$F:$F,Workshops!$A:$A=J11))"),"(ALTARS 2026) - 4th Workshop on Augmented Intelligence in Technology-Assisted Review Systems Giorgio Maria Di Nunzio, Evangelos Kanoulas and Prasenjit Majumder https://altars2026.dei.unipd.it/") -> (ALTARS 2026) - 4th Workshop on Augmented Intelligence in Technology-Assisted Review Systems Giorgio Maria Di Nunzio, Evangelos Kanoulas and Prasenjit Majumder https://altars2026.dei.unipd.it/ | K12: =IFERROR(__xludf.DUMMYFUNCTION("TEXTJOIN(CHAR(10), TRUE,FILTER(Workshops!$F:$F,Workshops!$A:$A=K11))"),"(AiOfAi) - The Workshop on Adverse Impacts and Collateral Effects of Artificial Intelligence Technologies Esma Aïmeur, Rim Ben Salem, Dorsaf Sallami, Julita Vassileva and Nora Boulahia-Cuppens https://sites.google.com/view/aiofai-2026/home") -> (AiOfAi) - The Workshop on Adverse Impacts and Collateral Effects of Artificial Intelligence Technologies Esma Aïmeur, Rim Ben Salem, Dorsaf Sallami, Julita Vassileva and Nora Boulahia-Cuppens https://sites.google.com/view/aiofai-2026/home | L12: =IFERROR(__xludf.DUMMYFUNCTION("TEXTJOIN(CHAR(10), TRUE,FILTER(Workshops!$F:$F,Workshops!$A:$A=L11))"),"(TrustFM) - Trustworthy Foundation Models for Web Intelligence: Causal Perspectives and Challenges Haoang Chi Qi Wang Jiantong Jiang Jiangchao Yao Feng Liu Bo Han https://www-tfm-causal.github.io/www2026-workshop/") -> (TrustFM) - Trustworthy Foundation Models for Web Intelligence: Causal Perspectives and Challenges Haoang Chi Qi Wang Jiantong Jiang Jiangchao Yao Feng Liu Bo Han https://www-tfm-causal.github.io/www2026-workshop/ | M12: =IFERROR(__xludf.DUMMYFUNCTION("TEXTJOIN(CHAR(10), TRUE,FILTER('PhD Symposium'!$D:$D,'PhD Symposium'!$E:$E=M11))"),"Tutoring Large Language Models to be Domain-adaptive, Precise, and Safe Somnath Banerjee LeTCC-ZK: Smooth, Verifiable Distributed Inference via Spline-Coded Computing Ekaterina Pavlova Edge-Mamba: Efficient and Robust Security Evaluation for the Web of "&"Things via Selective State Spaces Chenchong Du Towards Conversational Dataset Discovery on the Web Lisa-Yao Gan Constructing the Cycle of Mastery: LLM-Empowered Intelligent Tutoring for Programming Education Junfeng Zhang ") -> Tutoring Large Language Models to be Domain-adaptive, Precise, and Safe Somnath Banerjee LeTCC-ZK: Smooth, Verifiable Distributed Inference via Spline-Coded Computing Ekaterina Pavlova Edge-Mamba: Efficient and Robust Security Evaluation for the Web of Things via Selective State Spaces Chenchong Du Towards Conversational Dataset Discovery on the Web Lisa-Yao Gan Constructing the Cycle of Mastery: LLM-Empowered Intelligent Tutoring for Programming Education Junfeng Zhang | N12: https://www.w4a.info/2026/
A13: 13:00 - 14:00 | B13: Break
A14: 14:00 - 17:30 | B14: tut 5 | C14: tut 12 | D14: tut 13 | E14: tut 14 | F14: wk0502 | G14: wk0602 | H14: wk1602 | I14: wk1802 | J14: wk0800 | K14: wk1200 | M14: PhD Symposium Part 2 | N14: Web4All
B15: =IFERROR(__xludf.DUMMYFUNCTION("TEXTJOIN(CHAR(10), TRUE,FILTER(Tutorials!$E:$E,Tutorials!$A:$A=B14))"),"LLM-Enhanced Web-Centric Spatio-Temporal Intelligence: Methods, Applications, and Frontier Research Zijian Zhang, Hao Miao, Yuxuan Liang, Yan Zhao and Irwin King") -> LLM-Enhanced Web-Centric Spatio-Temporal Intelligence: Methods, Applications, and Frontier Research Zijian Zhang, Hao Miao, Yuxuan Liang, Yan Zhao and Irwin King | C15: =IFERROR(__xludf.DUMMYFUNCTION("TEXTJOIN(CHAR(10), TRUE,FILTER(Tutorials!$E:$E,Tutorials!$A:$A=C14))"),"Generalist Model for Structured Data: Foundations, Frontiers and Applications Peng Cui, Xingxuan Zhang, Han-Jia Ye, Jintai Chen and Shuyang Li") -> Generalist Model for Structured Data: Foundations, Frontiers and Applications Peng Cui, Xingxuan Zhang, Han-Jia Ye, Jintai Chen and Shuyang Li | D15: =IFERROR(__xludf.DUMMYFUNCTION("TEXTJOIN(CHAR(10), TRUE,FILTER(Tutorials!$E:$E,Tutorials!$A:$A=D14))"),"Robust Graph Learning on the Web: Challenges, Methods, and Applications Xiang Ao, Yang Liu, Guansong Pang, Yuanhao Ding, Hezhe Qiao, Dawei Cheng and Qing He") -> Robust Graph Learning on the Web: Challenges, Methods, and Applications Xiang Ao, Yang Liu, Guansong Pang, Yuanhao Ding, Hezhe Qiao, Dawei Cheng and Qing He | E15: =IFERROR(__xludf.DUMMYFUNCTION("TEXTJOIN(CHAR(10), TRUE,FILTER(Tutorials!$E:$E,Tutorials!$A:$A=E14))"),"Responsible Prompting on the Web: Governance, Mini-Evaluation, and Readiness with ChatGPT Manali Sharma and Ayush Garg") -> Responsible Prompting on the Web: Governance, Mini-Evaluation, and Readiness with ChatGPT Manali Sharma and Ayush Garg | F15: =IFERROR(__xludf.DUMMYFUNCTION("TEXTJOIN(CHAR(10), TRUE,FILTER(Workshops!$F:$F,Workshops!$A:$A=F14))"),"(DHOW-MiLLA) part 2 - Joint Workshop on Diffusion of Harmful Content on Online Web and Countering Misinformation in the Age of LLMs and Agents Thomas Mandl, Haiming Liu, Gautam Kishore Shahi, Amit Kumar Jaiswal, Durgesh Nandini, Luis-Daniel Ibáñez, Junich"&"i Suga, Dai Yamamoto, Rahul Mishra, Rajakrishnan P. Rajkumar, Sagar Uprety, Sujit Kuma and Bornali Phukon https://dhow-workshop.github.io/2026/") -> (DHOW-MiLLA) part 2 - Joint Workshop on Diffusion of Harmful Content on Online Web and Countering Misinformation in the Age of LLMs and Agents Thomas Mandl, Haiming Liu, Gautam Kishore Shahi, Amit Kumar Jaiswal, Durgesh Nandini, Luis-Daniel Ibáñez, Junichi Suga, Dai Yamamoto, Rahul Mishra, Rajakrishnan P. Rajkumar, Sagar Uprety, Sujit Kuma and Bornali Phukon https://dhow-workshop.github.io/2026/ | G15: =IFERROR(__xludf.DUMMYFUNCTION("TEXTJOIN(CHAR(10), TRUE,FILTER(Workshops!$F:$F,Workshops!$A:$A=G14))"),"(FAAW) part 2 - International Workshop on Foundations and Architectures for the Agentic Web Abderrahmane Maaradji, Abul Ehtesham, Aditi Singh, Boualem Benatallah, Fatma Outay, Luca Muscariello, Pradyumna Chari, Ramesh Raskar, Sabrina Senatore and Yacine S"&"am https://faaw.univ-tours.fr/") -> (FAAW) part 2 - International Workshop on Foundations and Architectures for the Agentic Web Abderrahmane Maaradji, Abul Ehtesham, Aditi Singh, Boualem Benatallah, Fatma Outay, Luca Muscariello, Pradyumna Chari, Ramesh Raskar, Sabrina Senatore and Yacine Sam https://faaw.univ-tours.fr/ | H15: =IFERROR(__xludf.DUMMYFUNCTION("TEXTJOIN(CHAR(10), TRUE,FILTER(Workshops!$F:$F,Workshops!$A:$A=H14))"),"(TempWeb) part 2 - The 16th Temporal Web Analytics Workshop Marc Spaniol, France Omar Alonso and Ricardo Baeza-Yates https://temporalweb.net/") -> (TempWeb) part 2 - The 16th Temporal Web Analytics Workshop Marc Spaniol, France Omar Alonso and Ricardo Baeza-Yates https://temporalweb.net/ | I15: =IFERROR(__xludf.DUMMYFUNCTION("TEXTJOIN(CHAR(10), TRUE,FILTER(Workshops!$F:$F,Workshops!$A:$A=I14))"),"(TIME) part 2 - 2nd International Workshop on Transformative Insights in Multi-faceted Evaluation Lei Wang, Md Zakir Hossain, Tom Gedeon, Syed Mohammed Shamsul Islam. Rafiqul Islam. Yasmeen George and Shreya Ghosh https://time.griffith.edu.au/workshop/"&"time2026/") -> (TIME) part 2 - 2nd International Workshop on Transformative Insights in Multi-faceted Evaluation Lei Wang, Md Zakir Hossain, Tom Gedeon, Syed Mohammed Shamsul Islam. Rafiqul Islam. Yasmeen George and Shreya Ghosh https://time.griffith.edu.au/workshop/time2026/ | J15: =IFERROR(__xludf.DUMMYFUNCTION("TEXTJOIN(CHAR(10), TRUE,FILTER(Workshops!$F:$F,Workshops!$A:$A=J14))"),"(FL@FM) - International Workshop on Federated Foundation Models for the Web 2026 Irwin King, Guodong Long, Zenglin Xu, Han Yu, Xiaoli Tang and Liping Yi https://federated-learning.org/fl@fm-www-2026/") -> (FL@FM) - International Workshop on Federated Foundation Models for the Web 2026 Irwin King, Guodong Long, Zenglin Xu, Han Yu, Xiaoli Tang and Liping Yi https://federated-learning.org/fl@fm-www-2026/ | K15: =IFERROR(__xludf.DUMMYFUNCTION("TEXTJOIN(CHAR(10), TRUE,FILTER(Workshops!$F:$F,Workshops!$A:$A=K14))"),"(MM4SG) - Fourth International Workshop on Multimodal Content Analysis for Social Good Usman Naseem, Surendrabikram Thapa, Roy Ka-Wei Lee and Mehwish Nasim https://sites.google.com/view/mm4sg-webconf26") -> (MM4SG) - Fourth International Workshop on Multimodal Content Analysis for Social Good Usman Naseem, Surendrabikram Thapa, Roy Ka-Wei Lee and Mehwish Nasim https://sites.google.com/view/mm4sg-webconf26 | M15: =IFERROR(__xludf.DUMMYFUNCTION("TEXTJOIN(CHAR(10), TRUE,FILTER('PhD Symposium'!$D:$D,'PhD Symposium'!$E:$E=M14))"),"Foundational Representations for Efficient Retrieval of Structured Tabular Data Inwon Kang Exploring Political Attitudes under Selective Media Consumption with Large Language Models Upasana Dutta How the Web Remembers Multilingual Collective Memory on W"&"ikipedia and in Large Language Models H. Laurie Lawson Can You Trust the Data Trust? An Ning Shen Introducing Temporal Dynamics to Proactive Recommender Systems for Email Outreach Čeněk Žid ") -> Foundational Representations for Efficient Retrieval of Structured Tabular Data Inwon Kang Exploring Political Attitudes under Selective Media Consumption with Large Language Models Upasana Dutta How the Web Remembers Multilingual Collective Memory on Wikipedia and in Large Language Models H. Laurie Lawson Can You Trust the Data Trust? An Ning Shen Introducing Temporal Dynamics to Proactive Recommender Systems for Email Outreach Čeněk Žid | N15: https://www.w4a.info/2026/
A18: 46204
A19: 10:00 - 10:30 | B19: Conference Opening
A20: 10:30 - 11:30 | B20: Keynote #1: Katrina Liggett
A21: 11:30 - 12:00 | B21: Break
A22: 12:00 - 13:30 | B22: Econ1 | C22: Graph1 | D22: Graph7 | E22: Search1 | F22: Semantics3 | G22: Social1 | H22: Systems1 | I22: Security3 | J22: Mining1 | K22: RecSys1 | L22: Industry1 | M22: Industry2 | N22: History1
B23: =IFERROR(__xludf.DUMMYFUNCTION("TEXTJOIN(CHAR(10), TRUE,FILTER('Sessions Counts'!$B:$B,'Sessions Counts'!$A:$A=B22))"),"Social Dynamics, Voting, and Consensus") -> Social Dynamics, Voting, and Consensus | C23: =IFERROR(__xludf.DUMMYFUNCTION("TEXTJOIN(CHAR(10), TRUE,FILTER('Sessions Counts'!$B:$B,'Sessions Counts'!$A:$A=C22))"),"Graph Foundation Models 1") -> Graph Foundation Models 1 | D23: =IFERROR(__xludf.DUMMYFUNCTION("TEXTJOIN(CHAR(10), TRUE,FILTER('Sessions Counts'!$B:$B,'Sessions Counts'!$A:$A=D22))"),"Anomaly Detection") -> Anomaly Detection | E23: =IFERROR(__xludf.DUMMYFUNCTION("TEXTJOIN(CHAR(10), TRUE,FILTER('Sessions Counts'!$B:$B,'Sessions Counts'!$A:$A=E22))"),"Zero-Shot & Graph RAG") -> Zero-Shot & Graph RAG | F23: =IFERROR(__xludf.DUMMYFUNCTION("TEXTJOIN(CHAR(10), TRUE,FILTER('Sessions Counts'!$B:$B,'Sessions Counts'!$A:$A=F22))"),"Logical Reasoning & Graph Understanding") -> Logical Reasoning & Graph Understanding | G23: =IFERROR(__xludf.DUMMYFUNCTION("TEXTJOIN(CHAR(10), TRUE,FILTER('Sessions Counts'!$B:$B,'Sessions Counts'!$A:$A=G22))"),"Opinion Dynamics and Misinformation") -> Opinion Dynamics and Misinformation | H23: =IFERROR(__xludf.DUMMYFUNCTION("TEXTJOIN(CHAR(10), TRUE,FILTER('Sessions Counts'!$B:$B,'Sessions Counts'!$A:$A=H22))"),"Client-Adaptive Federated Learning") -> Client-Adaptive Federated Learning | I23: =IFERROR(__xludf.DUMMYFUNCTION("TEXTJOIN(CHAR(10), TRUE,FILTER('Sessions Counts'!$B:$B,'Sessions Counts'!$A:$A=I22))"),"Fingerprinting") -> Fingerprinting | J23: =IFERROR(__xludf.DUMMYFUNCTION("TEXTJOIN(CHAR(10), TRUE,FILTER('Sessions Counts'!$B:$B,'Sessions Counts'!$A:$A=J22))"),"Sequence and Temporal Pattern Mining") -> Sequence and Temporal Pattern Mining | K23: =IFERROR(__xludf.DUMMYFUNCTION("TEXTJOIN(CHAR(10), TRUE,FILTER('Sessions Counts'!$B:$B,'Sessions Counts'!$A:$A=K22))"),"Multi-Behavior User Modeling") -> Multi-Behavior User Modeling | L23: =IFERROR(__xludf.DUMMYFUNCTION("TEXTJOIN(CHAR(10), TRUE,FILTER('Industry assignment'!$B:$B,'Industry assignment'!$A:$A=L22))"),"Financial Intelligence & Market Simulation") -> Financial Intelligence & Market Simulation | M23: =IFERROR(__xludf.DUMMYFUNCTION("TEXTJOIN(CHAR(10), TRUE,FILTER('Sessions Counts'!$B:$B,'Sessions Counts'!$A:$A=M22))"),"Generative & Next-Gen Recommendation Architectures") -> Generative & Next-Gen Recommendation Architectures
B24: =IFERROR(__xludf.DUMMYFUNCTION("TEXTJOIN(CHAR(10), TRUE,FILTER('Research assignment'!$D:$D,'Research assignment'!$F:$F=B22))"),"Opinion Dynamics with Multiple Adversaries Akhil Jalan and Marios Papachristou Aggregating Information and Preferences under Different Coordination Ability Qishen Han, Grant Schoenebeck, Biaoshuai Tao and Lirong Xia The Art of Two-Round Voting Qishen Ha"&"n, Grant Schoenebeck, Biaoshuai Tao and Lirong Xia The Price of Uncertainty for Social Consensus Yunzhe Bai and Alec Sun Social Deliberation: Democratic Deliberation Through Unbiased Social Interactions Dana Afazeli, Mohamad Latifian and Masoud Seddighi"&"n ") -> Opinion Dynamics with Multiple Adversaries Akhil Jalan and Marios Papachristou Aggregating Information and Preferences under Different Coordination Ability Qishen Han, Grant Schoenebeck, Biaoshuai Tao and Lirong Xia The Art of Two-Round Voting Qishen Han, Grant Schoenebeck, Biaoshuai Tao and Lirong Xia The Price of Uncertainty for Social Consensus Yunzhe Bai and Alec Sun Social Deliberation: Democratic Deliberation Through Unbiased Social Interactions Dana Afazeli, Mohamad Latifian and Masoud Seddighin | C24: =IFERROR(__xludf.DUMMYFUNCTION("TEXTJOIN(CHAR(10), TRUE,FILTER('Research assignment'!$D:$D,'Research assignment'!$F:$F=C22))"),"Topology-Aware Feature Sorting Enables Universal Modeling on Homophilic and Heterophilic Graphs Yi Wang, Jitao Zhao, Dongxiao He, Jia Li, Yuxiao Huang and Zhiyong Feng A Graph Foundation Model for Unified Anomaly Detection Renda Han, Xiaobao Wang, Luzhi "&"Wang, Wenxin Zhang, Guangzhen Yao and Hongxiang Liang RAG-GFM: Overcoming In-Memory Bottlenecks in Graph Foundation Models via Retrieval-Augmented Generation Haonan Yuan, Qingyun Sun, Jiacheng Tao, Xingcheng Fu and Jianxin Li Towards Graph Foundation Mo"&"del: Node Feature Transfer Invariant Modeling on General Graphs Jitao Zhao, Yi Wang, Yawen Li, Dongxiao He, Di Jin, Zhiyong Feng and Weixiong Zhang GraphRAG-R1: Graph Retrieval-Augmented Generation with Process-Constrained Reinforcement Learning Chuanyue"&" Yu, Kuo Zhao, Yuhan Li, Heng Chang, Mingjian Feng, Xiangzhe Jiang, Yufei Sun, Jia Li, Yuzhi Zhang, Qingyun Sun, Jianxin Li and Ziwei Zhang ") -> Topology-Aware Feature Sorting Enables Universal Modeling on Homophilic and Heterophilic Graphs Yi Wang, Jitao Zhao, Dongxiao He, Jia Li, Yuxiao Huang and Zhiyong Feng A Graph Foundation Model for Unified Anomaly Detection Renda Han, Xiaobao Wang, Luzhi Wang, Wenxin Zhang, Guangzhen Yao and Hongxiang Liang RAG-GFM: Overcoming In-Memory Bottlenecks in Graph Foundation Models via Retrieval-Augmented Generation Haonan Yuan, Qingyun Sun, Jiacheng Tao, Xingcheng Fu and Jianxin Li Towards Graph Foundation Model: Node Feature Transfer Invariant Modeling on General Graphs Jitao Zhao, Yi Wang, Yawen Li, Dongxiao He, Di Jin, Zhiyong Feng and Weixiong Zhang GraphRAG-R1: Graph Retrieval-Augmented Generation with Process-Constrained Reinforcement Learning Chuanyue Yu, Kuo Zhao, Yuhan Li, Heng Chang, Mingjian Feng, Xiangzhe Jiang, Yufei Sun, Jia Li, Yuzhi Zhang, Qingyun Sun, Jianxin Li and Ziwei Zhang | D24: =IFERROR(__xludf.DUMMYFUNCTION("TEXTJOIN(CHAR(10), TRUE,FILTER('Research assignment'!$D:$D,'Research assignment'!$F:$F=D22))"),"Unsupervised Subgraph Anomaly Detection based on Pattern Collaboration Sun Jiayang, Liu Shenghao, Deng Xianjun, Xiang Wei, Luo Meng, Zhang Qiankun and Zheng Dandan DP-DGAD: A Generalist Dynamic Graph Anomaly Detector with Dynamic Prototypes Jialun Zheng,"&" Jie Liu, Jiannong Cao, Xiao Wang, Hanchen Yang and Yankai Chen Anomaly Detection of Interaction Behaviors in Streaming Graphs Shuai Ren, Fan Zhang, Bolin Wang, Xiang Zhao and Zhihong Tian PAGE: Progressive Anomaly Generation Network for Semi-supervised"&" Graph Anomaly Detection Ting Guo, Dongyu Pei, Gangzhu Qiao, Kaixuan Yao and Da Wang Cross-Type Semantic Alignment for Multi-Type Anomaly Detection in Heterogeneous Graphs Di Jin, Xiao Huang, Xiaobao Wang, Fengyu Yan, Luzhi Wang and Hongxiang Liang ") -> Unsupervised Subgraph Anomaly Detection based on Pattern Collaboration Sun Jiayang, Liu Shenghao, Deng Xianjun, Xiang Wei, Luo Meng, Zhang Qiankun and Zheng Dandan DP-DGAD: A Generalist Dynamic Graph Anomaly Detector with Dynamic Prototypes Jialun Zheng, Jie Liu, Jiannong Cao, Xiao Wang, Hanchen Yang and Yankai Chen Anomaly Detection of Interaction Behaviors in Streaming Graphs Shuai Ren, Fan Zhang, Bolin Wang, Xiang Zhao and Zhihong Tian PAGE: Progressive Anomaly Generation Network for Semi-supervised Graph Anomaly Detection Ting Guo, Dongyu Pei, Gangzhu Qiao, Kaixuan Yao and Da Wang Cross-Type Semantic Alignment for Multi-Type Anomaly Detection in Heterogeneous Graphs Di Jin, Xiao Huang, Xiaobao Wang, Fengyu Yan, Luzhi Wang and Hongxiang Liang | E24: =IFERROR(__xludf.DUMMYFUNCTION("TEXTJOIN(CHAR(10), TRUE,FILTER('Research assignment'!$D:$D,'Research assignment'!$F:$F=E22))"),"QuiZSF: A Retrieval-Augmented Framework for Zero-Shot Time Series Forecasting Shichao Ma, Zhengyang Zhou, Qihe Huang, Binwu Wang and Yang Wang SDR-CIR: Semantic Debias Retrieval Framework for Training-Free Zero-Shot Composed Image Retrieval Yi Sun, Jinyu"&" Xu, Qing Xie, Jiachen Li, Yanchun Ma and Yongjian Liu FlowRAG: Continual Learning for Dynamic Retriever in Retrieval-Augmented Generation Senlei Zhang, Tongjun Shi, Dandan Song, Luan Zhang, Shuhao Zhang, Xiaofei Liao and Hai Jin DA-RAG: Dynamic Attribu"&"ted Community Search for Retrieval-Augmented Generation Xingyuan Zeng, Zuohan Wu, Yue Wang, Chen Zhang, Quanming Yao, Libin Zheng and Jian Yin HyperRAG: Reasoning N-ary Facts over Hypergraphs for Retrieval Augmented Generation Wen-Sheng Lien, Yu-Kai Chan"&", Hao-Lung Hsiao, Bo-Kai Ruan, Meng-Fen Chiang, Chien-An Chen, Yi-Ren Yeh and Hong-Han Shuai ") -> QuiZSF: A Retrieval-Augmented Framework for Zero-Shot Time Series Forecasting Shichao Ma, Zhengyang Zhou, Qihe Huang, Binwu Wang and Yang Wang SDR-CIR: Semantic Debias Retrieval Framework for Training-Free Zero-Shot Composed Image Retrieval Yi Sun, Jinyu Xu, Qing Xie, Jiachen Li, Yanchun Ma and Yongjian Liu FlowRAG: Continual Learning for Dynamic Retriever in Retrieval-Augmented Generation Senlei Zhang, Tongjun Shi, Dandan Song, Luan Zhang, Shuhao Zhang, Xiaofei Liao and Hai Jin DA-RAG: Dynamic Attributed Community Search for Retrieval-Augmented Generation Xingyuan Zeng, Zuohan Wu, Yue Wang, Chen Zhang, Quanming Yao, Libin Zheng and Jian Yin HyperRAG: Reasoning N-ary Facts over Hypergraphs for Retrieval Augmented Generation Wen-Sheng Lien, Yu-Kai Chan, Hao-Lung Hsiao, Bo-Kai Ruan, Meng-Fen Chiang, Chien-An Chen, Yi-Ren Yeh and Hong-Han Shuai | F24: =IFERROR(__xludf.DUMMYFUNCTION("TEXTJOIN(CHAR(10), TRUE,FILTER('Research assignment'!$D:$D,'Research assignment'!$F:$F=F22))"),"Unifying Deductive and Abductive Reasoning in Knowledge Graphs with Masked Diffusion Model Yisen Gao, Jiaxin Bai, Yi Huang, Xingcheng Fu, Qingyun Sun and Yangqiu Song Are LLMs Stable Formal Logic Translators in Logical Reasoning Across Linguistically Div"&"ersified Texts? Qingchuan Li, Jiatong Li, Zirui Liu, Mingyue Cheng, Yitong Zhou, Yuting Zeng, Qi Liu and Tongxuan Liu Matrix as Plan: Structured Logical Reasoning with Feedback-Driven Replanning Ke Chen, Jiandian Zeng, Zihao Peng, Guo Li, Guangxue Zhang "&"and Tian Wang GraphCogent: Mitigating LLMs' Working Memory Constraints via Multi-Agent Collaboration in Complex Graph Understanding Rongzheng Wang, Shuang Liang, Qizhi Chen, Yihong Huang, Muquan Li, Yizhuo Ma, Dongyang Zhang, Ke Qin and Man-Fai Leung La"&"rge Language Model for OWL Proofs Hui Yang, Jiaoyan Chen and Uli Sattler ") -> Unifying Deductive and Abductive Reasoning in Knowledge Graphs with Masked Diffusion Model Yisen Gao, Jiaxin Bai, Yi Huang, Xingcheng Fu, Qingyun Sun and Yangqiu Song Are LLMs Stable Formal Logic Translators in Logical Reasoning Across Linguistically Diversified Texts? Qingchuan Li, Jiatong Li, Zirui Liu, Mingyue Cheng, Yitong Zhou, Yuting Zeng, Qi Liu and Tongxuan Liu Matrix as Plan: Structured Logical Reasoning with Feedback-Driven Replanning Ke Chen, Jiandian Zeng, Zihao Peng, Guo Li, Guangxue Zhang and Tian Wang GraphCogent: Mitigating LLMs' Working Memory Constraints via Multi-Agent Collaboration in Complex Graph Understanding Rongzheng Wang, Shuang Liang, Qizhi Chen, Yihong Huang, Muquan Li, Yizhuo Ma, Dongyang Zhang, Ke Qin and Man-Fai Leung Large Language Model for OWL Proofs Hui Yang, Jiaoyan Chen and Uli Sattler | G24: =IFERROR(__xludf.DUMMYFUNCTION("TEXTJOIN(CHAR(10), TRUE,FILTER('Research assignment'!$D:$D,'Research assignment'!$F:$F=G22))"),"Rhythm of Opinion: Interpretable Hawkes-Graph Networks for Hierarchical Opinion Propagation Yulong Li, Zhixiang Lu, Peixin Guo, Simin Lai, Yuxuan Zhang, Haochen Xue, Xiwei Liu, Yichen Li, Zhaodong Wu, Feilong Tang, Mian Zhou, Chong Li, Imran Razzak, Qingx"&"ia Li and Jionglong Su PolicySim: An LLM-Based Agent Social Simulation Sandbox for Proactive Policy Optimization Renhong Huang, Ning Tang, Jiarong Xu, Yuxuan Cao, Qingqian Tu, Sheng Guo, Bo Zheng, Huiyuan Liu and Yang Yang Tracing Belief-Driven Thoughts"&" with Theory-of-Mind Agents: An Opinion Analysis Framework Jintao Wen, Yunfeng Ning, Hankun Kang, Xin Miao and Tieyun Qian DREAMS: A Social Exchange Theory-Informed Modeling of Misinformation Engagement on Social Media Lin Tian and Marian-Andrei Rizoiu "&"Cross-Platform Narrative Prediction: Leveraging Platform-Invariant Discourse Networks Patrick Gerard, Luca Luceri, Leonardo Blas and Emilio Ferrara ") -> Rhythm of Opinion: Interpretable Hawkes-Graph Networks for Hierarchical Opinion Propagation Yulong Li, Zhixiang Lu, Peixin Guo, Simin Lai, Yuxuan Zhang, Haochen Xue, Xiwei Liu, Yichen Li, Zhaodong Wu, Feilong Tang, Mian Zhou, Chong Li, Imran Razzak, Qingxia Li and Jionglong Su PolicySim: An LLM-Based Agent Social Simulation Sandbox for Proactive Policy Optimization Renhong Huang, Ning Tang, Jiarong Xu, Yuxuan Cao, Qingqian Tu, Sheng Guo, Bo Zheng, Huiyuan Liu and Yang Yang Tracing Belief-Driven Thoughts with Theory-of-Mind Agents: An Opinion Analysis Framework Jintao Wen, Yunfeng Ning, Hankun Kang, Xin Miao and Tieyun Qian DREAMS: A Social Exchange Theory-Informed Modeling of Misinformation Engagement on Social Media Lin Tian and Marian-Andrei Rizoiu Cross-Platform Narrative Prediction: Leveraging Platform-Invariant Discourse Networks Patrick Gerard, Luca Luceri, Leonardo Blas and Emilio Ferrara | H24: =IFERROR(__xludf.DUMMYFUNCTION("TEXTJOIN(CHAR(10), TRUE,FILTER('Research assignment'!$D:$D,'Research assignment'!$F:$F=H22))"),"FedBridge: Accelerating Edge-Assisted Federated Learning for Model-Heterogeneous Clients Kaibin Wang, Qiang He, Zeqian Dong, Ziteng Wei, Caslon Chua, Feifei Chen, Hai Jin and Yun Yang WinFLoRA: Incentivizing Client-Adaptive Aggregation in Federated LoRA "&"under Privacy Heterogeneity Mengsha Kou, Xiaoyu Xia, Ziqi Wang, Ibrahim Khalil, Ruikun Luo, Jingwen Zhou and Minhui Xue Beyond Class Boundaries: Federated Visual Primitive Sharing with Text-Guided Adaptation Yongqiang Huang, Yingyu Chen, Tao Wang, Zexin "&"Lu, Zerui Shao, Beibei Li and Yi Zhang CoLOR-DP: Conjugate Low-Rank Differential Privacy for Structure-Aware LoRA Fine-Tuning Kai Zhang, Yuxuan Xu, Wenxiang Lin, Chaoqun Hong, Pei-Wei Tsai, Xin Yuan and Minhui Xue CA-PFL: Client-adaptive Parameter-effic"&"ient Fine-tuning for Personalized Federated Learning Daixin Song, Hui Cai, Haojie Zhang, Biyun Sheng, Jian Zhou, Mang Ye and Fu Xiao ") -> FedBridge: Accelerating Edge-Assisted Federated Learning for Model-Heterogeneous Clients Kaibin Wang, Qiang He, Zeqian Dong, Ziteng Wei, Caslon Chua, Feifei Chen, Hai Jin and Yun Yang WinFLoRA: Incentivizing Client-Adaptive Aggregation in Federated LoRA under Privacy Heterogeneity Mengsha Kou, Xiaoyu Xia, Ziqi Wang, Ibrahim Khalil, Ruikun Luo, Jingwen Zhou and Minhui Xue Beyond Class Boundaries: Federated Visual Primitive Sharing with Text-Guided Adaptation Yongqiang Huang, Yingyu Chen, Tao Wang, Zexin Lu, Zerui Shao, Beibei Li and Yi Zhang CoLOR-DP: Conjugate Low-Rank Differential Privacy for Structure-Aware LoRA Fine-Tuning Kai Zhang, Yuxuan Xu, Wenxiang Lin, Chaoqun Hong, Pei-Wei Tsai, Xin Yuan and Minhui Xue CA-PFL: Client-adaptive Parameter-efficient Fine-tuning for Personalized Federated Learning Daixin Song, Hui Cai, Haojie Zhang, Biyun Sheng, Jian Zhou, Mang Ye and Fu Xiao | I24: =IFERROR(__xludf.DUMMYFUNCTION("TEXTJOIN(CHAR(10), TRUE,FILTER('Research assignment'!$D:$D,'Research assignment'!$F:$F=I22))"),"Reading Between the Lines: Towards Reliable Black-box LLM Fingerprinting via Zeroth-order Gradient Estimation Shuo Shao, Yiming Li, Hongwei Yao, Yifei Chen, Yuchen Yang and Zhan Qin Forge: A Robust Multi-tab Website Fingerprinting Attack via Blind Source"&" Separation Yitan Huang, Wei Qiao, Ding Wang, Meng Shen, Di Zhao, Linxu Li, Susu Cui, Bo Jiang, Zhigang Lu and Baoxu Liu HiFi-WF: Toward Realistic Website Fingerprinting with Multi-tab and Subpage Recognition Songyang Wu, Chuan Ma, Ming Ding, Long Yuan, "&"Biwen Chen, Yuwen Qian and Tao Xiang RoFiRe: Robust Website Fingerprinting on Real-World Tor Traffic via Improved Augmentation and Normalization Haeseung Jeon, Sujin Kim, Nate Mathews, Hosung Kang and Se Eun Oh Understanding Server-side Commercial Finge"&"rprinting Elisa Luo, Tom Ritter, Stefan Savage and Geoffrey M Voelker ") -> Reading Between the Lines: Towards Reliable Black-box LLM Fingerprinting via Zeroth-order Gradient Estimation Shuo Shao, Yiming Li, Hongwei Yao, Yifei Chen, Yuchen Yang and Zhan Qin Forge: A Robust Multi-tab Website Fingerprinting Attack via Blind Source Separation Yitan Huang, Wei Qiao, Ding Wang, Meng Shen, Di Zhao, Linxu Li, Susu Cui, Bo Jiang, Zhigang Lu and Baoxu Liu HiFi-WF: Toward Realistic Website Fingerprinting with Multi-tab and Subpage Recognition Songyang Wu, Chuan Ma, Ming Ding, Long Yuan, Biwen Chen, Yuwen Qian and Tao Xiang RoFiRe: Robust Website Fingerprinting on Real-World Tor Traffic via Improved Augmentation and Normalization Haeseung Jeon, Sujin Kim, Nate Mathews, Hosung Kang and Se Eun Oh Understanding Server-side Commercial Fingerprinting Elisa Luo, Tom Ritter, Stefan Savage and Geoffrey M Voelker | J24: =IFERROR(__xludf.DUMMYFUNCTION("TEXTJOIN(CHAR(10), TRUE,FILTER('Research assignment'!$D:$D,'Research assignment'!$F:$F=J22))"),"A Frequency-Aware Mixture of Heterogeneous Experts Framework for Knowledge Tracing Youheng Bai, Mingliang Hou, Teng Guo, Zitao Liu and Weiqi Luo Efficient High-Dimensional Time Series Forecasting with Transformers: A Channel Reordering Perspective Yuchen"&" Fang, Shiyu Wang, Yuxuan Liang, Zhou Ye, Yang Xiang, Yan Zhao and Kai Zheng Modeling Point-to-Point Dependency for High-Dimensional Long-Term Series Forecasting Xinyu Li, Kexi Chen, Ying Zheng, Zhiyi Yao, Yi Xie, Jihan Dai, Lei Bai, Jin Zhao, Jiajie She"&"n, Yunqi Cai, Hong Lu and Xin Wang Time-TK: A Multi-Offset Temporal Interaction Framework Combining Transformer and Kolmogorov-Arnold Networks for Time Series Forecasting Fan Zhang, Shiming Fan and Hua Wang FedDis: A Causal Disentanglement Framework for"&" Federated Traffic Prediction Chengyang Zhou, Zijian Zhang, Chunxu Zhang, Hao Miao, Yulin Zhang, Kedi Lyu and Juncheng Hu ") -> A Frequency-Aware Mixture of Heterogeneous Experts Framework for Knowledge Tracing Youheng Bai, Mingliang Hou, Teng Guo, Zitao Liu and Weiqi Luo Efficient High-Dimensional Time Series Forecasting with Transformers: A Channel Reordering Perspective Yuchen Fang, Shiyu Wang, Yuxuan Liang, Zhou Ye, Yang Xiang, Yan Zhao and Kai Zheng Modeling Point-to-Point Dependency for High-Dimensional Long-Term Series Forecasting Xinyu Li, Kexi Chen, Ying Zheng, Zhiyi Yao, Yi Xie, Jihan Dai, Lei Bai, Jin Zhao, Jiajie Shen, Yunqi Cai, Hong Lu and Xin Wang Time-TK: A Multi-Offset Temporal Interaction Framework Combining Transformer and Kolmogorov-Arnold Networks for Time Series Forecasting Fan Zhang, Shiming Fan and Hua Wang FedDis: A Causal Disentanglement Framework for Federated Traffic Prediction Chengyang Zhou, Zijian Zhang, Chunxu Zhang, Hao Miao, Yulin Zhang, Kedi Lyu and Juncheng Hu | K24: =IFERROR(__xludf.DUMMYFUNCTION("TEXTJOIN(CHAR(10), TRUE,FILTER('Research assignment'!$D:$D,'Research assignment'!$F:$F=K22))"),"ThinkRec: Thinking-based recommendation via LLM Qihang Yu, Kairui Fu, Zheqi Lv, Shengyu Zhang, Xinhui Wu, Chen Lin, Feng Wei, Bo Zheng and Fei Wu Iterative Semantic Reasoning from Individual to Group Interests for Generative Recommendation with LLMs Xiao"&"fei Zhu, Jinfei Chen, Feiyang Yuan and Yang Zhou Reinforcement Learning-Constrained Segmented User Modeling with Large Language Models for Recommendation Yu Xia, Qing Tan, He Chen, Jingyu Chen and Qian Dong Multi-Task Multi-Behavior Sequential Recommend"&"ation Weihao Du, Ziran Deng, Weike Pan and Zhong Ming RMBRec: Robust Multi-Behavior Recommendation towards Target Behaviors Miaomiao Cai, Zhijie Zhang, Junfeng Fang, Zhiyong Cheng, Xiang Wang and Meng Wang ") -> ThinkRec: Thinking-based recommendation via LLM Qihang Yu, Kairui Fu, Zheqi Lv, Shengyu Zhang, Xinhui Wu, Chen Lin, Feng Wei, Bo Zheng and Fei Wu Iterative Semantic Reasoning from Individual to Group Interests for Generative Recommendation with LLMs Xiaofei Zhu, Jinfei Chen, Feiyang Yuan and Yang Zhou Reinforcement Learning-Constrained Segmented User Modeling with Large Language Models for Recommendation Yu Xia, Qing Tan, He Chen, Jingyu Chen and Qian Dong Multi-Task Multi-Behavior Sequential Recommendation Weihao Du, Ziran Deng, Weike Pan and Zhong Ming RMBRec: Robust Multi-Behavior Recommendation towards Target Behaviors Miaomiao Cai, Zhijie Zhang, Junfeng Fang, Zhiyong Cheng, Xiang Wang and Meng Wang | L24: =IFERROR(__xludf.DUMMYFUNCTION("TEXTJOIN(CHAR(10), TRUE,FILTER('Industry assignment'!$D:$D,'Industry assignment'!$F:$F=L22))"),"FRiskGPT: A Generative Foundation Model for Financial Risk Detection Zhongjian Zhang, Mengmei Zhang, Dehua Xu, Rongjun Shi, Jianfeng Liu, Fuli Meng, Huajian Xu, Xiao Wang, Ruijia Wang, Junze Chen, Minwei Tang and Chuan Shi VeritasFi: An Adaptable, Multi-"&"tiered RAG Framework for Multi-modal Financial Question Answering Zhenghan Tai, Hanwei Wu, Qingchen Hu, Jijun Chi, Hailin He, Lei Ding, Tung Sum Thomas Kwok, Bohuai Xiao, Yuchen Hua, Suyuchen Wang, Peng Lu, Muzhi Li, Yihong Wu, Liheng Ma, Jerry Huang, Jia"&"yi Zhang, Gonghao Zhang, Chaolong Jiang, Jingrui Tian, Sicheng Lyu, Zeyu Li, Boyu Han, Fengran Mo, Xinyue Yu, Yufei Cui, Ling Zhou and Xinyu Wang When Agents Trade: Live Multi-Market Trading Arena for LLM Agents Lingfei Qian, Xueqing Peng, Hanley Smith, "&"Yi Han, Yueru He, Haohang Li, Yupeng Cao, Yangyang Yu, Guojun Xiong, Peng Lu, Yan Wang, Vincent Jim Zhang, Huan He, Alejandro Lopez-Lira, Jimin Huang, Jian-Yun Nie and Sophia Ananiadou Financial Wind Tunnel: A Retrieval-Augmented Market Simulator Bokai C"&"ao, Xueyuan Lin, Yiyan Qi, Chengjin Xu, Cehao Yang and Jian Guo FishFlow: A LLM-Empowered Dynamic Pricing Framework for Online Fleamarket Platform Kakam Chong, Xu Yan, Shuai Xiao, Ming Chen, Chen Ju, Fei Huang, Yuantao Gu, Shuguang Han and Jufeng Chen ") -> FRiskGPT: A Generative Foundation Model for Financial Risk Detection Zhongjian Zhang, Mengmei Zhang, Dehua Xu, Rongjun Shi, Jianfeng Liu, Fuli Meng, Huajian Xu, Xiao Wang, Ruijia Wang, Junze Chen, Minwei Tang and Chuan Shi VeritasFi: An Adaptable, Multi-tiered RAG Framework for Multi-modal Financial Question Answering Zhenghan Tai, Hanwei Wu, Qingchen Hu, Jijun Chi, Hailin He, Lei Ding, Tung Sum Thomas Kwok, Bohuai Xiao, Yuchen Hua, Suyuchen Wang, Peng Lu, Muzhi Li, Yihong Wu, Liheng Ma, Jerry Huang, Jiayi Zhang, Gonghao Zhang, Chaolong Jiang, Jingrui Tian, Sicheng Lyu, Zeyu Li, Boyu Han, Fengran Mo, Xinyue Yu, Yufei Cui, Ling Zhou and Xinyu Wang When Agents Trade: Live Multi-Market Trading Arena for LLM Agents Lingfei Qian, Xueqing Peng, Hanley Smith, Yi Han, Yueru He, Haohang Li, Yupeng Cao, Yangyang Yu, Guojun Xiong, Peng Lu, Yan Wang, Vincent Jim Zhang, Huan He, Alejandro Lopez-Lira, Jimin Huang, Jian-Yun Nie and Sophia Ananiadou Financial Wind Tunnel: A Retrieval-Augmented Market Simulator Bokai Cao, Xueyuan Lin, Yiyan Qi, Chengjin Xu, Cehao Yang and Jian Guo FishFlow: A LLM-Empowered Dynamic Pricing Framework for Online Fleamarket Platform Kakam Chong, Xu Yan, Shuai Xiao, Ming Chen, Chen Ju, Fei Huang, Yuantao Gu, Shuguang Han and Jufeng Chen | M24: =IFERROR(__xludf.DUMMYFUNCTION("TEXTJOIN(CHAR(10), TRUE,FILTER('Industry assignment'!$D:$D,'Industry assignment'!$F:$F=M22))"),"Hierarchical Semantic RL: Tackling the Problem of Dynamic Action Space for RL-based Recommendations Minmao Wang, Xingchen Liu, Shijie Yi, Likang Wu, Hongke Zhao, Fei Pan, Qingpeng Cai and Peng Jiang Beyond the Flat Sequence: Hierarchical and Preference-A"&"ware Generative Recommendations Zerui Chen, Heng Chang, Tianying Liu, Chuantian Zhou, Yi Cao, Jiandong Ding, Ming Liu and Bing Qin NEZHA: A Zero-sacrifice and Hyperspeed Decoding Architecture for Generative Recommendations Yejing Wang, Shengyu Zhou, Jiny"&"u Lu, Ziwei Liu, Langming Liu, Maolin Wang, Wenlin Zhang, Feng Li, Wenbo Su, Pengjie Wang, Jian Xu and Xiangyu Zhao OneTrans: Unified Feature Interaction and Sequence Modeling with One Transformer in Industrial Recommender Zhaoqi Zhang, Haolei Pei, Jun G"&"uo, Tianyu Wang, Yufei Feng, Hui Sun, Shaowei Liu and Aixin Sun GRADE: Personalized Multi-Task Fusion via Group-Relative Reinforcement Learning with Adaptive Dirichlet Exploration Tingfeng Hong, Pingye Ren, Xinlong Xiao, Chao Wang, Chenyi Lei, Wenwu Ou a"&"nd Han Li ") -> Hierarchical Semantic RL: Tackling the Problem of Dynamic Action Space for RL-based Recommendations Minmao Wang, Xingchen Liu, Shijie Yi, Likang Wu, Hongke Zhao, Fei Pan, Qingpeng Cai and Peng Jiang Beyond the Flat Sequence: Hierarchical and Preference-Aware Generative Recommendations Zerui Chen, Heng Chang, Tianying Liu, Chuantian Zhou, Yi Cao, Jiandong Ding, Ming Liu and Bing Qin NEZHA: A Zero-sacrifice and Hyperspeed Decoding Architecture for Generative Recommendations Yejing Wang, Shengyu Zhou, Jinyu Lu, Ziwei Liu, Langming Liu, Maolin Wang, Wenlin Zhang, Feng Li, Wenbo Su, Pengjie Wang, Jian Xu and Xiangyu Zhao OneTrans: Unified Feature Interaction and Sequence Modeling with One Transformer in Industrial Recommender Zhaoqi Zhang, Haolei Pei, Jun Guo, Tianyu Wang, Yufei Feng, Hui Sun, Shaowei Liu and Aixin Sun GRADE: Personalized Multi-Task Fusion via Group-Relative Reinforcement Learning with Adaptive Dirichlet Exploration Tingfeng Hong, Pingye Ren, Xinlong Xiao, Chao Wang, Chenyi Lei, Wenwu Ou and Han Li | N24: =IFERROR(__xludf.DUMMYFUNCTION("TEXTJOIN(CHAR(10), TRUE,FILTER('HoW assignment'!$D:$D,'HoW assignment'!$F:$F=N22))"),"Welcome by History of Web Chairs Wendy Hall and Oshani Seneviratne Seoul Test of Time Winner Presentation - LINE: Large-scale Information Network Embedding Jian Tang The Pendulum of Verbosity: The Evolution of Search from Blue Links to Agents Evgeniy Ga"&"brilovich ") -> Welcome by History of Web Chairs Wendy Hall and Oshani Seneviratne Seoul Test of Time Winner Presentation - LINE: Large-scale Information Network Embedding Jian Tang The Pendulum of Verbosity: The Evolution of Search from Blue Links to Agents Evgeniy Gabrilovich
A25: 13:30 - 14:30 | B25: Posters and Demos Session 1
B26: Demos1 | C26: ShortPapers1 | D26: =IFERROR(__xludf.DUMMYFUNCTION("ARRAY_CONSTRAIN(TRANSPOSE(FILTER('All Counts'!B:B, RIGHT(TO_TEXT('All Counts'!B:B), 1)=""1"")), 1, 11)"),"EconPoster1") -> EconPoster1 | E26: =IFERROR(__xludf.DUMMYFUNCTION("""COMPUTED_VALUE"""),"GraphPoster1") -> GraphPoster1 | F26: =IFERROR(__xludf.DUMMYFUNCTION("""COMPUTED_VALUE"""),"SearchPoster1") -> SearchPoster1 | G26: =IFERROR(__xludf.DUMMYFUNCTION("""COMPUTED_VALUE"""),"SemanticsPoster1") -> SemanticsPoster1 | H26: =IFERROR(__xludf.DUMMYFUNCTION("""COMPUTED_VALUE"""),"SecurityPoster1") -> SecurityPoster1 | I26: =IFERROR(__xludf.DUMMYFUNCTION("""COMPUTED_VALUE"""),"SocialPoster1") -> SocialPoster1 | J26: =IFERROR(__xludf.DUMMYFUNCTION("""COMPUTED_VALUE"""),"SystemsPoster1") -> SystemsPoster1 | K26: =IFERROR(__xludf.DUMMYFUNCTION("""COMPUTED_VALUE"""),"RecSysPoster1") -> RecSysPoster1 | L26: =IFERROR(__xludf.DUMMYFUNCTION("""COMPUTED_VALUE"""),"MiningPoster1") -> MiningPoster1 | M26: =IFERROR(__xludf.DUMMYFUNCTION("""COMPUTED_VALUE"""),"IndustryPoster1") -> IndustryPoster1 | N26: =IFERROR(__xludf.DUMMYFUNCTION("""COMPUTED_VALUE"""),"Web4GoodPoster1") -> Web4GoodPoster1
